Workbook

Sheet Cover
B1: HINDUSTAN UNILEVER
B2: NSE:HINDUNILVR
B4: 3-STATEMENT FINANCIAL MODEL & DCF VALUATION
B6: DATE PREPARED: | F6: 46138 | I6: LAST UPDATED: | M6: =NOW() -> 46139.657
B7: PREPARED BY: AKASHDEEP MUKHERJEE
B9: TABLE OF CONTENTS | F9: VALUATION SUMMARY | K9: MODEL COLOR CODING LEGEND
B10: 1. 3 STATEMENT MODEL | F10: CURRENT MARKET PRICE | H10: 2364 | K10: BLUE TEXT: HARDCODED INPUTS & HISTORICAL ACTUALS
B12: 2. DCF VALUATION & SENSITIVITY ANALYSIS | F12: IMPLIED SHARE PRICE (DCF) | H12: =DCF!C36 -> 938.31514 | K12: BLACK TEXT: CALCULATIONS WITHIN THE SAME SHEET
F14: IMPLIED UPSIDE/ (DOWNSIDE) (AS PER IMPLIED SHARE PRICE (DCF)) | H14: =DCF!C38 -> -0.60003617 | K14: GREEN TEXT: LINKS TO OTHER SHEETS IN THIS WORKBOOK

Sheet 3 Statement Model
C1: HISTORICALS | H1: FORECASTS
B2: PARTICULARS | C2: 2021 | D2: 2022 | E2: 2023 | F2: 2024 | G2: 2025 | H2: 2026 | I2: 2027 | J2: 2028 | K2: 2029 | L2: 2030
B3: ASSUMPTIONS
B4: Segment Revenue
B5: Homecare | C5: 13957 | D5: 16570 | E5: 21223 | F5: 21882 | G5: 22958 | H5: =G5*(1+H6) -> 24105.9 | I5: =H5*(1+I6) -> 25431.725 | J5: =I5*(1+J6) -> 26957.628 | K5: =J5*(1+K6) -> 28575.086 | L5: =K5*(1+L6) -> 30289.591
D6: =(D5-C5)/C5 -> 0.18721788 | E6: =(E5-D5)/D5 -> 0.28080869 | F6: =(F5-E5)/E5 -> 0.031051218 | G6: =(G5-F5)/F5 -> 0.049172836 | H6: 0.05 | I6: 0.055 | J6: 0.06 | K6: 0.06 | L6: 0.06
B7: Beauty & Personal Care | C7: 18038 | D7: 19567 | E7: 22022 | F7: 22448 | G7: 22689 | H7: =G7*(1+H8) -> 23823.45 | I7: =H7*(1+I8) -> 25014.623 | J7: =I7*(1+J8) -> 26265.354 | K7: =J7*(1+K8) -> 27578.621 | L7: =K7*(1+L8) -> 28957.552
D8: =(D7-C7)/C7 -> 0.084765495 | E8: =(E7-D7)/D7 -> 0.12546635 | F8: =(F7-E7)/E7 -> 0.019344292 | G8: =(G7-F7)/F7 -> 0.010735923 | H8: 0.05 | I8: 0.05 | J8: 0.05 | K8: 0.05 | L8: 0.05
B9: Foods & Refreshments | C9: 13204 | D9: 14105 | E9: 14876 | F9: 15291 | G9: 15294 | H9: =G9*(1+H10) -> 15752.82 | I9: =H9*(1+I10) -> 16304.169 | J9: =I9*(1+J10) -> 16956.335 | K9: =J9*(1+K10) -> 17634.589 | L9: =K9*(1+L10) -> 18339.972
D10: =(D9-C9)/C9 -> 0.068236898 | E10: =(E9-D9)/D9 -> 0.054661468 | F10: =(F9-E9)/E9 -> 0.027897284 | G10: =(G9-F9)/F9 -> 0.00019619384 | H10: 0.03 | I10: 0.035 | J10: 0.04 | K10: 0.04 | L10: 0.04
B11: Others | C11: 1829 | D11: 2204 | E11: 2459 | F11: 2275 | G11: 2180 | H11: =G11*(1+H12) -> 2180 | I11: =H11*(1+I12) -> 2180 | J11: =I11*(1+J12) -> 2180 | K11: =J11*(1+K12) -> 2180 | L11: =K11*(1+L12) -> 2180
D12: =(D11-C11)/C11 -> 0.20503007 | E12: =(E11-D11)/D11 -> 0.11569873 | F12: =(F11-E11)/E11 -> -0.074827166 | G12: =(G11-F11)/F11 -> -0.041758242 | H12: 0 | I12: 0 | J12: 0 | K12: 0 | L12: 0
B13: Total | C13: =SUM(C11+C9+C7+C5) -> 47028 | D13: =SUM(D11+D9+D7+D5) -> 52446 | E13: =SUM(E11+E9+E7+E5) -> 60580 | F13: =SUM(F11+F9+F7+F5) -> 61896 | G13: =SUM(G11+G9+G7+G5) -> 63121 | H13: =SUM(H11+H9+H7+H5) -> 65862.17 | I13: =SUM(I11+I9+I7+I5) -> 68930.516 | J13: =SUM(J11+J9+J7+J5) -> 72359.317 | ... L13: =SUM(L11+L9+L7+L5) -> 79767.116
D14: =(D13-C13)/C13 -> 0.11520796 | E14: =(E13-D13)/D13 -> 0.15509286 | F14: =(F13-E13)/E13 -> 0.021723341 | G14: =(G13-F13)/F13 -> 0.019791263 | H14: =(H13-G13)/G13 -> 0.043427227 | I14: =(I13-H13)/H13 -> 0.046587376 | J14: =(J13-I13)/I13 -> 0.049742865 | K14: =(K13-J13)/J13 -> 0.049875799 | L14: =(L13-K13)/K13 -> 0.050005331
B16: Segment Mix
B17: Homecare | C17: =C5/C13 -> 0.29678064 | D17: =D5/D13 -> 0.31594402 | E17: =E5/E13 -> 0.35033014 | F17: =F5/F13 -> 0.3535285 | G17: =G5/G13 -> 0.36371414
B18: Beauty & Personal Care | C18: =C7/C13 -> 0.38355873 | D18: =D7/D13 -> 0.37308851 | E18: =E7/E13 -> 0.36351931 | F18: =F7/F13 -> 0.36267287 | G18: =G7/G13 -> 0.35945248
B19: Foods & Refreshments | C19: =C9/C13 -> 0.2807689 | D19: =D9/D13 -> 0.26894329 | E19: =E9/E13 -> 0.24555959 | F19: =F9/F13 -> 0.24704343 | G19: =G9/G13 -> 0.24229654
B20: Others | C20: =C11/C13 -> 0.038891724 | D20: =D11/D13 -> 0.042024177 | E20: =E11/E13 -> 0.040590954 | F20: =F11/F13 -> 0.036755202 | G20: =G11/G13 -> 0.034536842
B22: Other Income Assumptions
B23: Other Income (%) | D23: =(D86-C86)/C86 -> -0.37073171 | E23: =(E86-D86)/D86 -> 0.98449612 | F23: =(F86-E86)/E86 -> 0.58398438 | G23: =(G86-F86)/F86 -> 0.2540074 | H23: 0.06 | I23: 0.06 | J23: 0.06 | K23: 0.06 | L23: 0.06
B25: COGS Assumptions
B26: COGS (% of Revenue) | C26: =C76/C75 -> 0.47095347 | D26: =D76/D75 -> 0.49069519 | E26: =E76/E75 -> 0.52353912 | F26: =F76/F75 -> 0.48080651 | G26: =G76/G75 -> 0.48443466 | H26: 0.49 | I26: 0.49 | J26: 0.49 | K26: 0.49 | L26: 0.49
B28: Margin Assumptions
B29: EBITDA Margin (%) | C29: =C83/C75 -> 0.24721443 | D29: =D83/D75 -> 0.24514739 | E29: =E83/E75 -> 0.23355893 | F29: =F83/F75 -> 0.23689738 | G29: =G83/G75 -> 0.23527828 | H29: 0.235 | I29: 0.235 | J29: 0.235 | K29: 0.235 | L29: 0.235
B31: Working Capital Assumptions
B32: Recievable Days | C32: =(C102/C75)*365 -> 13.644425 | D32: =(D102/D75)*365 -> 15.56153 | E32: =(E102/E75)*365 -> 18.551255 | F32: =(F102/F75)*365 -> 17.673275 | G32: =(G102/G75)*365 -> 22.083538 | H32: 20 | I32: 20 | J32: 20 | K32: 20 | L32: 20
B33: Inventory Days | C33: =(C101/C76)*365 -> 58.982075 | D33: =(D101/D76)*365 -> 58.093647 | E33: =(E101/E76)*365 -> 48.922153 | F33: =(F101/F76)*365 -> 49.328965 | G33: =(G101/G76)*365 -> 52.700471 | H33: 50 | I33: 50 | J33: 50 | K33: 50 | L33: 50
B34: Payable Days | C34: =(C124/C76)*365 -> 145.05734 | D34: =(D124/D76)*365 -> 128.61162 | E34: =(E124/E76)*365 -> 110.1813 | F34: =(F124/F76)*365 -> 128.60853 | G34: =(G124/G76)*365 -> 135.06361 | H34: 130 | I34: 130 | J34: 130 | K34: 130 | L34: 130
B36: Lease Liabilities Assumption
B37: Lease Liabilities Growth (%) | D37: =(D118-C118)/C118 -> 0.069133398 | E37: =(E118-D118)/D118 -> 0.51821494 | F37: =(F118-E118)/E118 -> 0.092381524 | G37: =(G118-F118)/F118 -> 0.05601318 | H37: 0.075 | I37: 0.08 | J37: 0.085 | K37: 0.09 | L37: 0.095
B39: Other Liabilities (Provisions & Tax) Assumptions
B40: Other Liabilities (Provisions & Tax) Growth (%) | D40: =(D120-C120)/C120 -> 0.013321393 | E40: =(E120-D120)/D120 -> -0.020106054 | F40: =(F120-E120)/E120 -> 0.39526494 | G40: =(G120-F120)/F120 -> -0.045652877 | H40: 0 | I40: 0 | J40: 0 | K40: 0 | L40: 0
B42: CAPEX Assumptions
B43: CAPEX (% of Revenue) | C43: =-(C148/C75) -> 0.015756571 | D43: =-(D148/D75) -> 0.023357358 | E43: =-(E148/E75) -> 0.019379333 | F43: =-(F148/F75) -> 0.023717203 | G43: =-(G148/G75) -> 0.019866605 | H43: 0.03 | I43: 0.03 | J43: 0.03 | K43: 0.03 | L43: 0.03
B45: Tax Assumptions
B46: Tax Rate (%) | H46: 0.255 | I46: 0.255 | J46: 0.255 | K46: 0.255 | L46: 0.255
B48: Depreciation Assumptions
B49: Depreciation (% of Revenue) | C49: =C84/C75 -> 0.022837459 | D49: =D84/D75 -> 0.020802349 | E49: =E84/E75 -> 0.01876857 | F49: =F84/F75 -> 0.019645858 | G49: =G84/G75 -> 0.021466707 | H49: 0.023 | I49: 0.023 | J49: 0.023 | K49: 0.023 | L49: 0.023
B51: Expense of Employees Assumption
...

Sheet DCF
C1: HISTORICALS | H1: FORECASTS
B2: PARTICULARS | C2: 2021 | D2: 2022 | E2: 2023 | F2: 2024 | G2: 2025 | H2: 2026 | I2: 2027 | J2: 2028 | K2: 2029 | L2: 2030
B3: EBIT | H3: ='3 Statement Model'!H85 -> 14272.666 | I3: ='3 Statement Model'!I85 -> 14937.592 | J3: ='3 Statement Model'!J85 -> 15680.631 | K3: ='3 Statement Model'!K85 -> 16462.715 | L3: ='3 Statement Model'!L85 -> 17285.938
B4: Less: Taxes on EBIT | H4: =H3*'3 Statement Model'!H46 -> 3639.5299 | I4: =I3*'3 Statement Model'!I46 -> 3809.086 | J4: =J3*'3 Statement Model'!J46 -> 3998.5609 | K4: =K3*'3 Statement Model'!K46 -> 4197.9923 | L4: =L3*'3 Statement Model'!L46 -> 4407.9143
B5: NOPAT (Net Operating Profit After Tax) | H5: =H3-H4 -> 10633.136 | I5: =I3-I4 -> 11128.506 | J5: =J3-J4 -> 11682.07 | K5: =K3-K4 -> 12264.723 | L5: =L3-L4 -> 12878.024
B6: (+) Depreciation & Amortization | H6: ='3 Statement Model'!H84 -> 1514.8299 | I6: ='3 Statement Model'!I84 -> 1585.4019 | J6: ='3 Statement Model'!J84 -> 1664.2643 | K6: ='3 Statement Model'!K84 -> 1747.2708 | L6: ='3 Statement Model'!L84 -> 1834.6437
B7: (-) Capital Expenditures (CAPEX) | H7: =-'3 Statement Model'!H148 -> 1975.8651 | I7: =-'3 Statement Model'!I148 -> 2067.9155 | J7: =-'3 Statement Model'!J148 -> 2170.7795 | K7: =-'3 Statement Model'!K148 -> 2279.0489 | L7: =-'3 Statement Model'!L148 -> 2393.0135
B8: (+/-) Changes in Working Capital | H8: =SUM('3 Statement Model'!H138:H141) -> -1099.4694 | I8: =SUM('3 Statement Model'!I138:I141) -> 161.40339 | J8: =SUM('3 Statement Model'!J138:J141) -> 180.36434 | K8: =SUM('3 Statement Model'!K138:K141) -> 189.84217 | L8: =SUM('3 Statement Model'!L138:L141) -> 199.82833
B9: Unlevered Free Cash Flow (UFCF) | H9: =H5+H6-H7+H8 -> 9072.6317 | I9: =I5+I6-I7+I8 -> 10807.396 | J9: =J5+J6-J7+J8 -> 11355.919 | K9: =K5+K6-K7+K8 -> 11922.787 | L9: =L5+L6-L7+L8 -> 12519.483
B10: Discount Period | H10: 0.5 | I10: 1.5 | J10: 2.5 | K10: 3.5 | L10: 4.5
B11: Discount Factor | H11: =1/(1+$C$24)^H10 -> 0.95346259 | I11: =1/(1+$C$24)^I10 -> 0.86678417 | J11: =1/(1+$C$24)^J10 -> 0.78798561 | K11: =1/(1+$C$24)^K10 -> 0.71635056 | L11: =1/(1+$C$24)^L10 -> 0.65122778
B12: Present Value (PV) of UFCF | H12: =H9*H11 -> 8650.415 | I12: =I9*I11 -> 9367.6798 | J12: =J9*J11 -> 8948.3009 | K12: =K9*K11 -> 8540.8949 | L12: =L9*L11 -> 8153.0349
B14: Risk Free Rate | C14: 0.07
B15: Equity Risk Premium | C15: 0.06
B16: Beta | C16: 0.5
B17: Market Capitalization | C17: 490000
B18: Cost of Equity (Ke) | C18: =C14+(C16*C15) -> 0.1
B19: Pre-Tax Cost of Debt | C19: 0.075
B20: Tax Rate | C20: 0.255
B21: After-Tax Cost of Debt (Kd) | C21: =C19*(1-C20) -> 0.055875
B22: Weight of Equity | C22: 1
B23: Weight of Debt | C23: 0
B24: WACC | C24: =(C22*C18)+(C23*C21) -> 0.1
B26: Sum of PV of UCFC | C26: =SUM(H12:L12) -> 43660.325
B27: Terminal Growth Rate | C27: 0.05
B28: Terminal Value (TV) | C28: =L9*(1+C27)/(C24-C27) -> 262909.14
B29: Implied Exit EV/EBITDA | C29: =C28/'3 Statement Model'!L83 -> 13.750059
B30: PV of Terminal Value (TV) | C30: =C28/(1+C24)^L10 -> 171213.73
B31: Enterprise Value (EV) | C31: =C30+C26 -> 214874.06
B32: Less: Total Debt | C32: ='3 Statement Model'!G117+'3 Statement Model'!G118+'3 Statement Model'!G123 -> 1924
B33: Add: Cash and Cash Equivalents | C33: ='3 Statement Model'!G103 -> 7554
B34: Implied Equity Value | C34: =C31-C32+C33 -> 220504.06
B35: Outstanding Shares (in millions) | C35: 235
B36: Implied Share Price | C36: =(C34/C35) -> 938.31514
B37: Current Market Price | C37: 2346
B38: Upside / (Downside) vs CMP | C38: =(C36-C37)/C37 -> -0.60003617
B41: SENSETIVITY ANALYSIS
C42: =C36 -> 938.31514 | D42: 0.04 | E42: 0.045 | F42: 0.05 | G42: 0.055 | H42: 0.06 | I42: 0.065 | J42: 0.07
C43: 0.085 | D43: 1069.0738 | E43: 1180.3012 | F43: 1323.3079 | G43: 1513.9836 | H43: 1780.9294 | I43: 2181.3482 | J43: 2848.7128
C44: 0.09 | D44: 965.88405 | E44: 1053.4456 | F44: 1162.8975 | G44: 1303.6213 | H44: 1491.2531 | I44: 1753.9377 | J44: 2147.9645
...
