Workbook

Sheet Cover
B1: HINDUSTAN UNILEVER LIMITED (HUL)
B2: #VALUE! | C2: NSE: HINDUNILVER
B4: PROJECT: 3-STATEMENT FINANCIAL MODEL & DCF VALUATION
B6: DATE: APRIL 1ST, 2026
B7: PREPARED BY: AKASHDEEP MUKHERJEE
B10: TABLE OF CONTENTS | G10: VALUATION SUMMARY | L10: MODEL COLOR CODING LEGEND
B11: 1. ASSUMPTIONS & DRIVERS | G11: CURRENT MARKET PRICE | I11: =DCF!C39 -> 2083.6 | L11: BLUE TEXT: HARDCODED INPUTS & HISTORICAL ACTUALS
B12: 2. INCOME STATEMENT | G12: IMPLIED SHARE PRICE (DCF) | I12: =DCF!C38 -> 1072.9168 | L12: BLACK TEXT: CALCULATIONS WITHIN THE SAME SHEET
B13: 3. BALANCE SHEET | G13: IMPLIED UPSIDE/(DOWNSIDE): | I13: =DCF!C40 -> -0.48506584 | L13: GREEN TEXT: LINKS TO OTHER SHEETS IN THIS WORKBOOK
B14: 4. CASH FLOW STATEMENT | G14: OVERVALUED/UNDERVALUED | I14: =IF(I11>I12,"OVERVALUED","UNDERVALUED") -> OVERVALUED
B15: 5. DCF VALUATION & SENSETIVITY ANALYSIS

Sheet Assumptions
B1: Assumptions & Drivers — HINDUSTAN UNILEVER
C3: ACTUALS | H3: FORECAST
C4: 2021 | D4: =C4+1 -> 2022 | E4: =D4+1 -> 2023 | F4: =E4+1 -> 2024 | G4: =F4+1 -> 2025 | H4: =G4+1 -> 2026 | I4: =H4+1 -> 2027 | J4: =I4+1 -> 2028 | K4: =J4+1 -> 2029
B5: REVENUE DRIVERS
B6: Revenue from Operations | C6: ='Income Statement'!C6 -> 47028 | D6: ='Income Statement'!D6 -> 52446 | E6: ='Income Statement'!E6 -> 60580 | F6: ='Income Statement'!F6 -> 61896 | G6: ='Income Statement'!G6 -> 63121 | H6: =G6+(H7*G6) -> 66908.26 | I6: =H6+(I7*H6) -> 71591.838 | J6: =I6+(J7*I6) -> 77319.185 | K6: =J6+(K7*J6) -> 83504.72
B7: YoY Revenue from Operations Growth % | D7: =(D6/C6)-1 -> 0.11520796 | E7: =(E6/D6)-1 -> 0.15509286 | F7: =(F6/E6)-1 -> 0.021723341 | G7: =(G6/F6)-1 -> 0.019791263 | H7: 0.06 | I7: 0.07 | J7: 0.08 | K7: 0.08
B8: Other Income | C8: ='Income Statement'!C7 -> 410 | D8: ='Income Statement'!D7 -> 258 | E8: ='Income Statement'!E7 -> 512 | F8: ='Income Statement'!F7 -> 811 | G8: ='Income Statement'!G7 -> 1017 | H8: =G8+(H9*G8) -> 1149.21 | I8: =H8+(I9*H8) -> 1298.6073 | J8: =I8+(J9*I8) -> 1467.4262 | K8: =J8+(K9*J8) -> 1658.1917
B9: YoY Other Revenue Growth % | D9: =(D8/C8)-1 -> -0.37073171 | E9: =(E8/D8)-1 -> 0.98449612 | F9: =(F8/E8)-1 -> 0.58398438 | G9: =(G8/F8)-1 -> 0.2540074 | H9: 0.13 | I9: 0.13 | J9: 0.13 | K9: 0.13
B11: PROFITABILITY DRIVERS
B12: Gross Margin % {(Revenue-COGS)/Revenue} | C12: =('Income Statement'!C6-'Income Statement'!N11)/'Income Statement'!C6 -> 0.52904653 | D12: =('Income Statement'!D6-'Income Statement'!O11)/'Income Statement'!D6 -> 0.50930481 | E12: =('Income Statement'!E6-'Income Statement'!P11)/'Income Statement'!E6 -> 0.47646088 | F12: =('Income Statement'!F6-'Income Statement'!Q11)/'Income Statement'!F6 -> 0.51919349 | G12: =('Income Statement'!G6-'Income Statement'!R11)/'Income Statement'!G6 -> 0.51556534 | H12: =AVERAGE($F$12:$G$12) -> 0.51737941 | I12: =AVERAGE($F$12:$G$12) -> 0.51737941 | J12: =AVERAGE($F$12:$G$12) -> 0.51737941 | K12: =AVERAGE($F$12:$G$12) -> 0.51737941
B13: EBITDA Margin % (EBITDA/Revenue) | C13: ='Income Statement'!N13/'Income Statement'!C6 -> 0.25344476 | D13: ='Income Statement'!O13/'Income Statement'!D6 -> 0.24804561 | E13: ='Income Statement'!P13/'Income Statement'!E6 -> 0.24011225 | F13: ='Income Statement'!Q13/'Income Statement'!F6 -> 0.24453923 | G13: ='Income Statement'!R13/'Income Statement'!G6 -> 0.24500562 | H13: =AVERAGE($F$13:$G$13) -> 0.24477243 | I13: =AVERAGE($F$13:$G$13) -> 0.24477243 | J13: =AVERAGE($F$13:$G$13) -> 0.24477243 | K13: =AVERAGE($F$13:$G$13) -> 0.24477243
B14: EBIT Margin % (EBIT/Revenue) | C14: ='Income Statement'!N15/'Income Statement'!C6 -> 0.2306073 | D14: ='Income Statement'!O15/'Income Statement'!D6 -> 0.22724326 | E14: ='Income Statement'!P15/'Income Statement'!E6 -> 0.22134368 | F14: ='Income Statement'!Q15/'Income Statement'!F6 -> 0.22489337 | G14: ='Income Statement'!R15/'Income Statement'!G6 -> 0.22353892 | H14: =AVERAGE($F$14:$G$14) -> 0.22421614 | I14: =AVERAGE($F$14:$G$14) -> 0.22421614 | J14: =AVERAGE($F$14:$G$14) -> 0.22421614 | K14: =AVERAGE($F$14:$G$14) -> 0.22421614
B15: Effective Tax Rate % (Total Tax/PBT) | C15: =-('Income Statement'!C25+'Income Statement'!C26)/'Income Statement'!C22 -> 0.24570998 | D15: =-('Income Statement'!D25+'Income Statement'!D26)/'Income Statement'!D22 -> 0.25155803 | E15: =-('Income Statement'!E25+'Income Statement'!E26)/'Income Statement'!E22 -> 0.23986512 | F15: =-('Income Statement'!F25+'Income Statement'!F26)/'Income Statement'!F22 -> 0.26166882 | G15: =-('Income Statement'!G25+'Income Statement'!G26)/'Income Statement'!G22 -> 0.25972945 | H15: =AVERAGE($F$15:$G$15) -> 0.26069913 | I15: =AVERAGE($F$15:$G$15) -> 0.26069913 | J15: =AVERAGE($F$15:$G$15) -> 0.26069913 | K15: =AVERAGE($F$15:$G$15) -> 0.26069913
B17: WORKING CAPITAL DRIVERS
B18: Debtor Days (DSO) {(Trade Recievables/Revenue)*365} | C18: =('Balance Sheet'!C26/'Income Statement'!C6)*365 -> 13.644425 | D18: =('Balance Sheet'!D26/'Income Statement'!D6)*365 -> 15.56153 | E18: =('Balance Sheet'!E26/'Income Statement'!E6)*365 -> 18.551255 | F18: =('Balance Sheet'!F26/'Income Statement'!F6)*365 -> 17.673275 | G18: =('Balance Sheet'!G26/'Income Statement'!G6)*365 -> 22.083538 | H18: 20 | I18: 20 | J18: 20 | K18: 20
B19: Inventory Days (DIO) {(Inventories/COGS)*365} | C19: =('Balance Sheet'!C22/('Income Statement'!C11+'Income Statement'!C12+'Income Statement'!C13))*365 -> 58.982075 | D19: =('Balance Sheet'!D22/('Income Statement'!D11+'Income Statement'!D12+'Income Statement'!D13))*365 -> 58.093647 | E19: =('Balance Sheet'!E22/('Income Statement'!E11+'Income Statement'!E12+'Income Statement'!E13))*365 -> 48.922153 | F19: =('Balance Sheet'!F22/('Income Statement'!F11+'Income Statement'!F12+'Income Statement'!F13))*365 -> 49.328965 | G19: =('Balance Sheet'!G22/('Income Statement'!G11+'Income Statement'!G12+'Income Statement'!G13))*365 -> 52.700471 | H19: 50 | I19: 50 | J19: 50 | K19: 50
B20: Creditor Days (DPO) {(Trade Payables/COGS)*365} | C20: =(('Balance Sheet'!C55+'Balance Sheet'!C56)/('Income Statement'!C11+'Income Statement'!C12+'Income Statement'!C13))*365 -> 145.05734 | D20: =(('Balance Sheet'!D55+'Balance Sheet'!D56)/('Income Statement'!D11+'Income Statement'!D12+'Income Statement'!D13))*365 -> 128.61162 | E20: =(('Balance Sheet'!E55+'Balance Sheet'!E56)/('Income Statement'!E11+'Income Statement'!E12+'Income Statement'!E13))*365 -> 110.1813 | F20: =(('Balance Sheet'!F55+'Balance Sheet'!F56)/('Income Statement'!F11+'Income Statement'!F12+'Income Statement'!F13))*365 -> 128.60853 | G20: =(('Balance Sheet'!G55+'Balance Sheet'!G56)/('Income Statement'!G11+'Income Statement'!G12+'Income Statement'!G13))*365 -> 135.06361 | H20: 130 | I20: 130 | J20: 130 | K20: 130
B22: CAPEX AND DEPRECIATION
B23: Capex | C23: 4051 | D23: 919 | E23: 1042 | F23: 1318 | G23: 1149
B24: Capex as % of Revenue (Capex/Revenue) | C24: =C23/'Income Statement'!C6 -> 0.086140172 | D24: =D23/'Income Statement'!D6 -> 0.017522785 | E24: =E23/'Income Statement'!E6 -> 0.017200396 | F24: =F23/'Income Statement'!F6 -> 0.021293783 | G24: =G23/'Income Statement'!G6 -> 0.018203134 | H24: 0.02 | I24: 0.02 | J24: 0.02 | K24: 0.02
B25: Depreciation as % of Net PPE | C25: ='Income Statement'!C16/'Balance Sheet'!C7 -> 0.17560497 | D25: ='Income Statement'!D16/'Balance Sheet'!D7 -> 0.176852 | E25: ='Income Statement'!E16/'Balance Sheet'!E7 -> 0.16362066 | F25: ='Income Statement'!F16/'Balance Sheet'!F7 -> 0.15141327 | G25: ='Income Statement'!G16/'Balance Sheet'!G7 -> 0.15710145
B26: Depreciation as % of Revenue | C26: ='Income Statement'!C16/'Income Statement'!C6 -> 0.022837459 | D26: ='Income Statement'!D16/'Income Statement'!D6 -> 0.020802349 | E26: ='Income Statement'!E16/'Income Statement'!E6 -> 0.01876857 | F26: ='Income Statement'!F16/'Income Statement'!F6 -> 0.019645858 | G26: ='Income Statement'!G16/'Income Statement'!G6 -> 0.021466707 | H26: =AVERAGE($C$26:$G$26) -> 0.020704188 | I26: =AVERAGE($C$26:$G$26) -> 0.020704188 | J26: =AVERAGE($C$26:$G$26) -> 0.020704188 | K26: =AVERAGE($C$26:$G$26) -> 0.020704188
B28: DIVIDEND AND PAYOUT
B29: Dividend per Share | C29: =SUM(C31:C33) -> 31 | D29: =SUM(D31:D33) -> 34 | E29: =SUM(E31:E33) -> 39 | F29: =SUM(F31:F33) -> 42 | G29: =SUM(G31:G33) -> 53
B30: Normalized Dividend per Share | C30: =C31+C32 -> 31 | D30: =D31+D32 -> 34 | E30: =E31+E32 -> 39 | F30: =F31+F32 -> 42 | G30: =G31+G32 -> 43 | H30: 40 | I30: 40 | J30: 40 | K30: 40
B31: Interim | C31: 14 | D31: 15 | E31: 17 | F31: 18 | G31: 19
B32: Final | C32: 17 | D32: 19 | E32: 22 | F32: 24 | G32: 24
B33: Special | C33: 0 | D33: 0 | E33: 0 | F33: 0 | G33: 10
B34: Dividend Payout Ratio (Total Dividend/PAT) | C34: =(C30*'Balance Sheet'!C37)/'Income Statement'!C27 -> 0.910625 | D34: =(D30*'Balance Sheet'!D37)/'Income Statement'!D27 -> 0.89906605 | E34: =(E30*'Balance Sheet'!E37)/'Income Statement'!E27 -> 0.90348975 | F34: =(F30*'Balance Sheet'!F37)/'Income Statement'!F27 -> 0.95992997 | G34: =(G30*'Balance Sheet'!G37)/'Income Statement'!G27 -> 0.94695905
B35: Finance Cost Growth % | H35: 0.05 | I35: 0.05 | J35: 0.05 | K35: 0.05
B36: Employee Expenses as % of Revenue | C36: ='Income Statement'!C14/'Income Statement'!C6 -> 0.050140342 | D36: ='Income Statement'!D14/'Income Statement'!D6 -> 0.048526103 | E36: ='Income Statement'!E14/'Income Statement'!E6 -> 0.047111258 | F36: ='Income Statement'!F14/'Income Statement'!F6 -> 0.048613804 | G36: ='Income Statement'!G14/'Income Statement'!G6 -> 0.048747643 | H36: =AVERAGE($C$36:$G$36) -> 0.04862783 | I36: =AVERAGE($C$36:$G$36) -> 0.04862783 | J36: =AVERAGE($C$36:$G$36) -> 0.04862783 | K36: =AVERAGE($C$36:$G$36) -> 0.04862783
B37: Other Expenses as % of Revenue | C37: ='Income Statement'!C17/'Income Statement'!C6 -> 0.23169176 | D37: ='Income Statement'!D17/'Income Statement'!D6 -> 0.21563132 | E37: ='Income Statement'!E17/'Income Statement'!E6 -> 0.19579069 | F37: ='Income Statement'!F17/'Income Statement'!F6 -> 0.23368231 | G37: ='Income Statement'!G17/'Income Statement'!G6 -> 0.23153942 | H37: =AVERAGE($C$37:$G$37) -> 0.2216671 | I37: =AVERAGE($C$37:$G$37) -> 0.2216671 | J37: =AVERAGE($C$37:$G$37) -> 0.2216671 | K37: =AVERAGE($C$37:$G$37) -> 0.2216671

Sheet Income Statement
B1: Income Statement - HINDUSTAN UNILEVER
C3: ACTUALS | H3: FORECAST
C4: 2021 | D4: =C4+1 -> 2022 | E4: =D4+1 -> 2023 | F4: =E4+1 -> 2024 | G4: =F4+1 -> 2025 | H4: =G4+1 -> 2026 | I4: =H4+1 -> 2027 | J4: =I4+1 -> 2028 | K4: =J4+1 -> 2029
B5: INCOME
B6: Revenue from Operations | C6: 47028 | D6: 52446 | E6: 60580 | F6: 61896 | G6: 63121 | H6: =Assumptions!H6 -> 66908.26 | I6: =Assumptions!I6 -> 71591.838 | J6: =Assumptions!J6 -> 77319.185 | K6: =Assumptions!K6 -> 83504.72
B7: Other Income | C7: 410 | D7: 258 | E7: 512 | F7: 811 | G7: 1017 | H7: =Assumptions!H8 -> 1149.21 | I7: =Assumptions!I8 -> 1298.6073 | J7: =Assumptions!J8 -> 1467.4262 | K7: =Assumptions!K8 -> 1658.1917
B8: TOTAL INCOME | C8: =SUM(C6:C7) -> 47438 | D8: =SUM(D6:D7) -> 52704 | E8: =SUM(E6:E7) -> 61092 | F8: =SUM(F6:F7) -> 62707 | G8: =SUM(G6:G7) -> 64138 | H8: =SUM(H6:H7) -> 68057.47 | I8: =SUM(I6:I7) -> 72890.446 | J8: =SUM(J6:J7) -> 78786.612 | K8: =SUM(K6:K7) -> 85162.912
B10: EXPENSES | N10: 2021 | O10: =N10+1 -> 2022 | P10: =O10+1 -> 2023 | Q10: =P10+1 -> 2024 | R10: =Q10+1 -> 2025 | S10: =R10+1 -> 2026 | T10: =S10+1 -> 2027 | U10: =T10+1 -> 2028 | V10: =U10+1 -> 2029
B11: Cost of Materials Consumed | C11: 15432 | D11: 16446 | E11: 20212 | F11: 19257 | G11: 19458 | H11: =S11 -> 32291.304 | I11: =T11 -> 34551.695 | J11: =U11 -> 37315.83 | K11: =V11 -> 40301.097 | M11: COGS | N11: =C11+C12+C13 -> 22148 | O11: =D11+D12+D13 -> 25735 | P11: =E11+E12+E13 -> 31716 | Q11: =F11+F12+F13 -> 29760 | R11: =G11+G12+G13 -> 30578 | S11: =H6*(1-Assumptions!H12) -> 32291.304 | T11: =I6*(1-Assumptions!I12) -> 34551.695 | U11: =J6*(1-Assumptions!J12) -> 37315.83 | V11: =K6*(1-Assumptions!K12) -> 40301.097
B12: Purchase of Stock in Trade | C12: 7121 | D12: 9311 | E12: 11579 | F12: 10514 | G12: 11273
B13: Changes in Inventories of finished goods (including stock in trade) and Work in Progress | C13: -405 | D13: -22 | E13: -75 | F13: -11 | G13: -153 | M13: EBITDA | N13: =C20+C16 -> 11919 | O13: =D20+D16 -> 13009 | P13: =E20+E16 -> 14546 | Q13: =F20+F16 -> 15136 | R13: =G20+G16 -> 15465 | S13: =H20+H16 -> 17266.453 | T13: =I20+I16 -> 18552.352 | U13: =J20+J16 -> 20114.535 | V13: =K20+K16 -> 21810.787
B14: Employee Benefits Expenses | C14: 2358 | D14: 2545 | E14: 2854 | F14: 3009 | G14: 3077 | H14: =H6*Assumptions!H36 -> 3253.6035 | I14: =I6*Assumptions!I36 -> 3481.3557 | J14: =J6*Assumptions!J36 -> 3759.8642 | K14: =K6*Assumptions!K36 -> 4060.6533
B15: Finance Costs | C15: 117 | D15: 106 | E15: 114 | F15: 334 | G15: 395 | H15: =(G15*Assumptions!H35)+G15 -> 414.75 | I15: =(H15*Assumptions!I35)+H15 -> 435.4875 | J15: =(I15*Assumptions!J35)+I15 -> 457.26188 | K15: =(J15*Assumptions!K35)+J15 -> 480.12497 | M15: EBIT | N15: =C20 -> 10845 | O15: =D20 -> 11918 | P15: =E20 -> 13409 | Q15: =F20 -> 13920 | R15: =G20 -> 14110 | S15: =H20 -> 15881.172 | T15: =I20 -> 17070.101 | U15: =J20 -> 18513.704 | V15: =K20 -> 20081.89
B16: Depreciation and Amortisation Expense | C16: 1074 | D16: 1091 | E16: 1137 | F16: 1216 | G16: 1355 | H16: =Assumptions!H26*'Income Statement'!H6 -> 1385.2812 | I16: =Assumptions!I26*'Income Statement'!I6 -> 1482.2509 | J16: =Assumptions!J26*'Income Statement'!J6 -> 1600.831 | K16: =Assumptions!K26*'Income Statement'!K6 -> 1728.8975
B17: Other Expenses | C17: 10896 | D17: 11309 | E17: 11861 | F17: 14464 | G17: 14615 | H17: =H6*Assumptions!H37 -> 14831.36 | I17: =I6*Assumptions!I37 -> 15869.555 | J17: =J6*Assumptions!J37 -> 17139.119 | K17: =K6*Assumptions!K37 -> 18510.249
B18: TOTAL EXPENSES | C18: =SUM(C11:C17) -> 36593 | D18: =SUM(D11:D17) -> 40786 | E18: =SUM(E11:E17) -> 47682 | F18: =SUM(F11:F17) -> 48783 | G18: =SUM(G11:G17) -> 50020 | H18: =SUM(H11:H17) -> 52176.298 | I18: =SUM(I11:I17) -> 55820.344 | J18: =SUM(J11:J17) -> 60272.907 | K18: =SUM(K11:K17) -> 65081.022
B20: Profit Before Exceptional Items and Tax | C20: 10845 | D20: 11918 | E20: 13409 | F20: 13920 | G20: 14110 | H20: =H8-H18 -> 15881.172 | I20: =I8-I18 -> 17070.101 | J20: =J8-J18 -> 18513.704 | K20: =K8-K18 -> 20081.89
B21: Exceptional Items (Net) | C21: -239 | D21: -44 | E21: -64 | F21: 6 | G21: 305 | H21: 0 | I21: 0 | J21: 0 | K21: 0
B22: Profit Before Tax from Continuing Operations | C22: =SUM(C20:C21) -> 10606 | D22: =SUM(D20:D21) -> 11874 | E22: =SUM(E20:E21) -> 13345 | F22: =SUM(F20:F21) -> 13926 | G22: =SUM(G20:G21) -> 14415 | H22: =SUM(H20:H21) -> 15881.172 | I22: =SUM(I20:I21) -> 17070.101 | J22: =SUM(J20:J21) -> 18513.704 | K22: =SUM(K20:K21) -> 20081.89
B24: Tax Expenses (Current + Deferred) | C24: =C25+C26 -> -2606 | D24: =D25+D26 -> -2987 | E24: =E25+E26 -> -3201 | F24: =F25+F26 -> -3644 | G24: =G25+G26 -> -3744 | H24: =H25+H26 -> -4140.2077 | I24: =I25+I26 -> -4450.1607 | J24: =J25+J26 -> -4826.5067 | K24: =K25+K26 -> -5235.3314
B25: Current Tax | C25: -2520 | D25: -2840 | E25: -3001 | F25: -3521 | G25: -3620 | H25: =-(H22*Assumptions!H15) -> -4140.2077 | I25: =-(I22*Assumptions!I15) -> -4450.1607 | J25: =-(J22*Assumptions!J15) -> -4826.5067 | K25: =-(K22*Assumptions!K15) -> -5235.3314
B26: Deffered Tax Charge | C26: -86 | D26: -147 | E26: -200 | F26: -123 | G26: -124 | H26: 0 | I26: 0 | J26: 0 | K26: 0
B27: Profit after Tax from Continuing Operations | C27: =C22+C24 -> 8000 | D27: =D22+D24 -> 8887 | E27: =E22+E24 -> 10144 | F27: =F22+F24 -> 10282 | G27: =G22+G24 -> 10671 | H27: =H22+H24 -> 11740.964 | I27: =I22+I24 -> 12619.941 | J27: =J22+J24 -> 13687.198 | K27: =K22+K24 -> 14846.559

Sheet Balance Sheet
B1: Balance Sheet - HINDUSTAN UNILEVER
C3: ACTUALS | H3: FORECAST
C4: 2021 | D4: =C4+1 -> 2022 | E4: =D4+1 -> 2023 | F4: =E4+1 -> 2024 | G4: =F4+1 -> 2025 | H4: =G4+1 -> 2026 | I4: =H4+1 -> 2027 | J4: =I4+1 -> 2028 | K4: =J4+1 -> 2029
B5: ASSETS
B6: Non-Current Assets
B7: Property, Plant and Equipment | C7: 6116 | D7: 6169 | E7: 6949 | F7: 8031 | G7: 8625 | H7: =G7+(Assumptions!H24*'Income Statement'!H6)-'Income Statement'!H16 -> 8577.884 | I7: =H7+(Assumptions!I24*'Income Statement'!I6)-'Income Statement'!I16 -> 8527.4698 | J7: =I7+(Assumptions!J24*'Income Statement'!J6)-'Income Statement'!J16 -> 8473.0225 | K7: =J7+(Assumptions!K24*'Income Statement'!K6)-'Income Statement'!K16 -> 8414.2195
B8: Capital Work-in-Progress | C8: 745 | D8: 1313 | E8: 1132 | F8: 1025 | G8: 1009 | H8: 1009 | I8: 1009 | J8: 1009 | K8: 1009
B9: Goodwill | C9: 17316 | D9: 17316 | E9: 17316 | F9: 17466 | G9: 17466 | H9: 17466 | I9: 17466 | J9: 17466 | K9: 17466
B10: Other Intangible Assets | C10: 27930 | D10: 27907 | E10: 28263 | F10: 28247 | G10: 28244 | H10: 28244 | I10: 28244 | J10: 28244 | K10: 28244
B11: Goodwill on Consolidation | C11: 81 | D11: 81 | E11: 150 | F11: 0 | G11: 0 | H11: 0 | I11: 0 | J11: 0 | K11: 0
B12: Investments accounted for using the equity method | C12: 0 | D12: 0 | E12: 69 | F12: 65 | G12: 57 | H12: 57 | I12: 57 | J12: 57 | K12: 57
B13: Financial Assets:
B14: Investments | C14: 2 | D14: 2 | E14: 2 | F14: 2 | G14: 2 | H14: 2 | I14: 2 | J14: 2 | K14: 2
B15: Loans | C15: 111 | D15: 115 | E15: 98 | F15: 102 | G15: 87 | H15: 87 | I15: 87 | J15: 87 | K15: 87
B16: Other Financial Assets | C16: 757 | D16: 729 | E16: 725 | F16: 760 | G16: 763 | H16: 763 | I16: 763 | J16: 763 | K16: 763
B17: Non-Current Tax Assets (Net) | C17: 1246 | D17: 1158 | E17: 1164 | F17: 1175 | G17: 1199 | H17: 1199 | I17: 1199 | J17: 1199 | K17: 1199
B18: Deffered tax Assets (Net) | C18: 17 | D18: 11 | E18: 10 | F18: 10 | G18: 17 | H18: 17 | I18: 17 | J18: 17 | K18: 17
B19: Other Non-Current Assets | C19: 219 | D19: 194 | E19: 211 | F19: 292 | G19: 360 | H19: 360 | I19: 360 | J19: 360 | K19: 360
B20: Total - Non-current assets (A) | C20: =SUM(C7:C19) -> 54540 | D20: =SUM(D7:D19) -> 54995 | E20: =SUM(E7:E19) -> 56089 | F20: =SUM(F7:F19) -> 57175 | G20: =SUM(G7:G19) -> 57829 | H20: =SUM(H7:H19) -> 57781.884 | I20: =SUM(I7:I19) -> 57731.47 | J20: =SUM(J7:J19) -> 57677.023 | K20: =SUM(K7:K19) -> 57618.219
B21: Current Assets
B22: Inventories | C22: 3579 | D22: 4096 | E22: 4251 | F22: 4022 | G22: 4415 | H22: =(Assumptions!H19/365)*'Income Statement'!S11 -> 4423.4663 | I22: =(Assumptions!I19/365)*'Income Statement'!T11 -> 4733.1089 | J22: =(Assumptions!J19/365)*'Income Statement'!U11 -> 5111.7576 | K22: =(Assumptions!K19/365)*'Income Statement'!V11 -> 5520.6982
B23: Financial Assets:
B24: Investments | C24: 2707 | D24: 3519 | E24: 2811 | F24: 4558 | G24: 3751 | H24: 3751 | I24: 3751 | J24: 3751 | K24: 3751
B25: Loans | C25: 34 | D25: 35 | E25: 36 | F25: 38 | G25: 46 | H25: 46 | I25: 46 | J25: 46 | K25: 46
B26: Trade Recievables | C26: 1758 | D26: 2236 | E26: 3079 | F26: 2997 | G26: 3819 | H26: =(Assumptions!H18/365)*'Income Statement'!H6 -> 3666.206 | I26: =(Assumptions!I18/365)*'Income Statement'!I6 -> 3922.8404 | J26: =(Assumptions!J18/365)*'Income Statement'!J6 -> 4236.6677 | K26: =(Assumptions!K18/365)*'Income Statement'!K6 -> 4575.6011
B27: Cash and Cash Equivalent | C27: 1842 | D27: 1147 | E27: 714 | F27: 825 | G27: 6071 | H27: ='Cashflow Statement'!H77 -> 8788.42 | I27: ='Cashflow Statement'!I77 -> 12296.569 | J27: ='Cashflow Statement'!J77 -> 16929.224 | K27: ='Cashflow Statement'!K77 -> 22748.958
B28: Bank Balances other than Cash and Cash Equivalents mentioned above | C28: 2629 | D28: 2699 | E28: 3964 | F28: 6734 | G28: 1483 | H28: 1483 | I28: 1483 | J28: 1483 | K28: 1483
B29: Other Financial Assets | C29: 1154 | D29: 1089 | E29: 1386 | F29: 1425 | G29: 1488 | H29: 1488 | I29: 1488 | J29: 1488 | K29: 1488
B30: Other Current Assets | C30: 497 | D30: 688 | E30: 745 | F30: 713 | G30: 955 | H30: 955 | I30: 955 | J30: 955 | K30: 955
B31: Assets Held for Sale | C31: 17 | D31: 13 | E31: 12 | F31: 12 | G31: 23 | H31: 23 | I31: 23 | J31: 23 | K31: 23
B32: Total - Current assets (B) | C32: =SUM(C22:C31) -> 14217 | D32: =SUM(D22:D31) -> 15522 | E32: =SUM(E22:E31) -> 16998 | F32: =SUM(F22:F31) -> 21324 | G32: =SUM(G22:G31) -> 22051 | H32: =SUM(H22:H31) -> 24624.092 | I32: =SUM(I22:I31) -> 28698.518 | J32: =SUM(J22:J31) -> 34023.65 | K32: =SUM(K22:K31) -> 40591.257
B33: TOTAL ASSETS (A+B) | C33: =C32+C20 -> 68757 | D33: =D32+D20 -> 70517 | E33: =E32+E20 -> 73087 | F33: =F32+F20 -> 78499 | G33: =G32+G20 -> 79880 | H33: =H32+H20 -> 82405.976 | I33: =I32+I20 -> 86429.988 | J33: =J32+J20 -> 91700.672 | K33: =K32+K20 -> 98209.477
B35: EQUITY AND LIABILITIES
B36: EQUITY
B37: Equity Share Capital | C37: 235 | D37: 235 | E37: 235 | F37: 235 | G37: 235 | H37: 235 | I37: 235 | J37: 235 | K37: 235
B38: Other Equity | C38: 47439 | D38: 48826 | E38: 50069 | F38: 50983 | G38: 49167 | H38: =G38+'Income Statement'!H27-Assumptions!H30*235 -> 51507.964 | I38: =H38+'Income Statement'!I27-Assumptions!I30*235 -> 54727.905 | J38: =I38+'Income Statement'!J27-Assumptions!J30*235 -> 59015.103 | K38: =J38+'Income Statement'!K27-Assumptions!K30*235 -> 64461.661
B39: Non-Controlling Interests | C39: 20 | D39: 26 | E39: 218 | F39: 205 | G39: 207 | H39: 207 | I39: 207 | J39: 207 | K39: 207
B40: Total - Equity (A) | C40: =SUM(C37:C39) -> 47694 | D40: =SUM(D37:D39) -> 49087 | E40: =SUM(E37:E39) -> 50522 | F40: =SUM(F37:F39) -> 51423 | G40: =SUM(G37:G39) -> 49609 | H40: =SUM(H37:H39) -> 51949.964 | I40: =SUM(I37:I39) -> 55169.905 | J40: =SUM(J37:J39) -> 59457.103 | K40: =SUM(K37:K39) -> 64903.661
B41: LIABILITIES
B42: Non-Current Liabilities
...

Sheet Cashflow Statement
B1: Cashflow Statement - HINDUSTAN UNILEVER
C3: ACTUALS | H3: FORECAST
C4: 2021 | D4: =C4+1 -> 2022 | E4: =D4+1 -> 2023 | F4: =E4+1 -> 2024 | G4: =F4+1 -> 2025 | H4: =G4+1 -> 2026 | I4: =H4+1 -> 2027 | J4: =I4+1 -> 2028 | K4: =J4+1 -> 2029
B5: CASHFLOW FROM OPERATING ACTIVITIES
B6: Profit Before Tax from Continuing Operations | C6: 10606 | D6: 11874 | E6: 13346 | F6: 13926 | G6: 14415 | H6: ='Income Statement'!H22 -> 15881.172 | I6: ='Income Statement'!I22 -> 17070.101 | J6: ='Income Statement'!J22 -> 18513.704 | K6: ='Income Statement'!K22 -> 20081.89
B7: Adjustments for:
B8: Depreciation and Amortisation | C8: 1134 | D8: 1106 | E8: 1152 | F8: 1216 | G8: 1363 | H8: ='Income Statement'!H16 -> 1385.2812 | I8: ='Income Statement'!I16 -> 1482.2509 | J8: ='Income Statement'!J16 -> 1600.831 | K8: ='Income Statement'!K16 -> 1728.8975
B9: (Profit)/Loss on Sale of Property, Plant and Equipment | C9: -57 | D9: -97 | E9: -100 | F9: 18 | G9: 43 | H9: 0 | I9: 0 | J9: 0 | K9: 0
B10: Government Grant Accrued (Net) | C10: 13 | D10: 0 | E10: 0 | F10: 0 | G10: 0 | H10: 0 | I10: 0 | J10: 0 | K10: 0
B11: Contingent consideration true up for business combination | C11: -22 | D11: -9 | E11: -2 | F11: 0 | G11: 0 | H11: 0 | I11: 0 | J11: 0 | K11: 0
B12: Fair value gain on financial liability on acquisition | C12: 0 | D12: 0 | E12: 0 | F12: -132 | G12: 120 | H12: 0 | I12: 0 | J12: 0 | K12: 0
B13: Finance Income | C13: -346 | D13: -198 | E13: -411 | F13: -546 | G13: -755 | H13: =-('Income Statement'!H7) -> -1149.21 | I13: =-('Income Statement'!I7) -> -1298.6073 | J13: =-('Income Statement'!J7) -> -1467.4262 | K13: =-('Income Statement'!K7) -> -1658.1917
B14: Dividend income | C14: -1 | D14: -1 | E14: -2 | F14: -3 | G14: 0 | H14: 0 | I14: 0 | J14: 0 | K14: 0
B15: Other non-operating income – Fair value (gain)/loss on investments | C15: -63 | D15: -59 | E15: -99 | F15: -249 | G15: -256 | H15: 0 | I15: 0 | J15: 0 | K15: 0
B16: Interest expense | C16: 117 | D16: 106 | E16: 114 | F16: 317 | G16: 372 | H16: ='Income Statement'!H15 -> 414.75 | I16: ='Income Statement'!I15 -> 435.4875 | J16: ='Income Statement'!J15 -> 457.26188 | K16: ='Income Statement'!K15 -> 480.12497
B17: Profit on sale of water purification business | C17: 0 | D17: 0 | E17: 0 | F17: 0 | G17: -595 | H17: 0 | I17: 0 | J17: 0 | K17: 0
B18: Movement in provision towards litigation | C18: 0 | D18: 0 | E18: 0 | F18: -159 | G18: 0 | H18: 0 | I18: 0 | J18: 0 | K18: 0
B19: Provision for expenses on employee stock options | C19: -1 | D19: -1 | E19: 1 | F19: 0 | G19: 0 | H19: 0 | I19: 0 | J19: 0 | K19: 0
B20: Profit on sale of brand rights | C20: 0 | D20: -29 | E20: -60 | F20: 0 | G20: 0 | H20: 0 | I20: 0 | J20: 0 | K20: 0
B21: Payment from Retirement Benefit Scheme Reserve | C21: 0 | D21: 0 | E21: -1 | F21: -1 | G21: -1 | H21: -1 | I21: -1 | J21: -1 | K21: -1
B22: Share of loss of joint venture | C22: 0 | D22: 0 | E22: 1 | F22: 4 | G22: 8 | H22: 0 | I22: 0 | J22: 0 | K22: 0
B23: Transaction cost from acquisition | C23: 0 | D23: 0 | E23: 2 | F23: 0 | G23: 0 | H23: 0 | I23: 0 | J23: 0 | K23: 0
B24: Inventory written off net of Provision/(write back) for Inventory | C24: 201 | D24: 156 | E24: 184 | F24: 167 | G24: 189 | H24: 0 | I24: 0 | J24: 0 | K24: 0
B25: Bad debts/assets written off net of Provision/(write back) | C25: 77 | D25: -15 | E25: -27 | F25: -11 | G25: 24 | H25: 0 | I25: 0 | J25: 0 | K25: 0
B26: Share based payment expense | C26: 0 | D26: 0 | E26: 0 | F26: 0 | G26: 11 | H26: 0 | I26: 0 | J26: 0 | K26: 0
B27: Mark-to-market loss/(gain) on derivative financial instruments | C27: 14 | D27: -4 | E27: -8 | F27: -10 | G27: 4 | H27: 0 | I27: 0 | J27: 0 | K27: 0
B28: Cash generated from operations before working capital changes | C28: =SUM(C6:C27) -> 11672 | D28: =SUM(D6:D27) -> 12829 | E28: =SUM(E6:E27) -> 14090 | F28: =SUM(F6:F27) -> 14537 | G28: =SUM(G6:G27) -> 14942 | H28: =SUM(H6:H27) -> 16530.993 | I28: =SUM(I6:I27) -> 17688.233 | J28: =SUM(J6:J27) -> 19103.371 | K28: =SUM(K6:K27) -> 20631.721
B29: Adjustments for:
B30: (Increase)/decrease in Non-Current Assets | C30: -4 | D30: 3 | E30: -14 | F30: -30 | G30: -87
B31: (Increase)/decrease in Current Assets | C31: -412 | D31: -480 | E31: -1111 | F31: 220 | G31: -1275 | H31: ='Balance Sheet'!G26-'Balance Sheet'!H26 -> 152.79397 | I31: ='Balance Sheet'!H26-'Balance Sheet'!I26 -> -256.63442 | J31: ='Balance Sheet'!I26-'Balance Sheet'!J26 -> -313.82724 | K31: ='Balance Sheet'!J26-'Balance Sheet'!K26 -> -338.93341
B32: (Increase)/decrease in Inventories | C32: -543 | D32: -758 | E32: -339 | F32: 74 | G32: -584 | H32: ='Balance Sheet'!G22-'Balance Sheet'!H22 -> -8.4662506 | I32: ='Balance Sheet'!H22-'Balance Sheet'!I22 -> -309.64264 | J32: ='Balance Sheet'!I22-'Balance Sheet'!J22 -> -378.64871 | K32: ='Balance Sheet'!J22-'Balance Sheet'!K22 -> -408.94061
B33: Increase/(decrease) in Non-Current Liabilities | C33: 28 | D33: 86 | E33: -116 | F33: 128 | G33: -284 | H33: 0 | I33: 0 | J33: 0 | K33: 0
B34: Increase/(decrease) in Current Liabilities | C34: 830 | D34: 149 | E34: 622 | F34: 921 | G34: 1442 | H34: =('Balance Sheet'!H55+'Balance Sheet'!H56)-('Balance Sheet'!G55+'Balance Sheet'!G56) -> 186.01225 | I34: =('Balance Sheet'!I55+'Balance Sheet'!I56)-('Balance Sheet'!H55+'Balance Sheet'!H56) -> 805.07086 | J34: =('Balance Sheet'!J55+'Balance Sheet'!J56)-('Balance Sheet'!I55+'Balance Sheet'!I56) -> 984.48665 | K34: =('Balance Sheet'!K55+'Balance Sheet'!K56)-('Balance Sheet'!J55+'Balance Sheet'!J56) -> 1063.2456
B35: Cash generated from operations | C35: =SUM(C28:C34) -> 11571 | D35: =SUM(D28:D34) -> 11829 | E35: =SUM(E28:E34) -> 13132 | F35: =SUM(F28:F34) -> 15850 | G35: =SUM(G28:G34) -> 14154 | H35: =SUM(H28:H34) -> 16861.333 | I35: =SUM(I28:I34) -> 17927.026 | J35: =SUM(J28:J34) -> 19395.382 | K35: =SUM(K28:K34) -> 20947.092
B36: Taxes paid (net of refunds) | C36: -2407 | D36: -2784 | E36: -3138 | F36: -381 | G36: -2268 | H36: ='Income Statement'!H24 -> -4140.2077 | I36: ='Income Statement'!I24 -> -4450.1607 | J36: ='Income Statement'!J24 -> -4826.5067 | K36: ='Income Statement'!K24 -> -5235.3314
B37: Profit/(Loss) from Joint venture | C37: 0 | D37: 0 | E37: -1 | F37: 0 | G37: 0 | H37: 0 | I37: 0 | J37: 0 | K37: 0
B38: Loss from discontinued operations | C38: -1 | D38: 3 | E38: -1 | F38: 0 | G38: 0 | H38: 0 | I38: 0 | J38: 0 | K38: 0
B39: Net cash generated from operating activities – [A] | C39: =SUM(C35:C38) -> 9163 | D39: =SUM(D35:D38) -> 9048 | E39: =SUM(E35:E38) -> 9992 | F39: =SUM(F35:F38) -> 15469 | G39: =SUM(G35:G38) -> 11886 | H39: =SUM(H35:H38) -> 12721.125 | I39: =SUM(I35:I38) -> 13476.866 | J39: =SUM(J35:J38) -> 14568.875 | K39: =SUM(K35:K38) -> 15711.761
B41: CASH FLOW FROM INVESTING ACTIVITIES:
B42: Purchase of property, plant and equipment | C42: -741 | D42: -1225 | E42: -1174 | F42: -1468 | G42: -1254 | H42: =-(Assumptions!H24*'Income Statement'!H6) -> -1338.1652 | I42: =-(Assumptions!I24*'Income Statement'!I6) -> -1431.8368 | J42: =-(Assumptions!J24*'Income Statement'!J6) -> -1546.3837 | K42: =-(Assumptions!K24*'Income Statement'!K6) -> -1670.0944
...

Sheet DCF
B1: FCFF CALCULATION
D3: ACTUALS | I3: FORECAST
D4: 2021 | E4: =D4+1 -> 2022 | F4: =E4+1 -> 2023 | G4: =F4+1 -> 2024 | H4: =G4+1 -> 2025 | I4: =H4+1 -> 2026 | J4: =I4+1 -> 2027 | K4: =J4+1 -> 2028 | L4: =K4+1 -> 2029
B5: EBIT | C5: PBIT + Finance Cost | D5: ='Income Statement'!N15 -> 10845 | E5: ='Income Statement'!O15 -> 11918 | F5: ='Income Statement'!P15 -> 13409 | G5: ='Income Statement'!Q15 -> 13920 | H5: ='Income Statement'!R15 -> 14110 | I5: ='Income Statement'!S15 -> 15881.172 | J5: ='Income Statement'!T15 -> 17070.101 | K5: ='Income Statement'!U15 -> 18513.704 | L5: ='Income Statement'!V15 -> 20081.89
B6: Tax Rate | C6: Effective Tax Rate | D6: =Assumptions!C15 -> 0.24570998 | E6: =Assumptions!D15 -> 0.25155803 | F6: =Assumptions!E15 -> 0.23986512 | G6: =Assumptions!F15 -> 0.26166882 | H6: =Assumptions!G15 -> 0.25972945 | I6: =Assumptions!H15 -> 0.26069913 | J6: =Assumptions!I15 -> 0.26069913 | K6: =Assumptions!J15 -> 0.26069913 | L6: =Assumptions!K15 -> 0.26069913
B7: NOPAT | C7: EBIT*(1-Tax Rate) | D7: =D5*(1-D6) -> 8180.2753 | E7: =E5*(1-E6) -> 8919.9314 | F7: =F5*(1-F6) -> 10192.649 | G7: =G5*(1-G6) -> 10277.57 | H7: =H5*(1-H6) -> 10445.217 | I7: =I5*(1-I6) -> 11740.964 | J7: =J5*(1-J6) -> 12619.941 | K7: =K5*(1-K6) -> 13687.198 | L7: =L5*(1-L6) -> 14846.559
B8: Add: Depreciation and Amortization | C8: Depreciation and Amortization | D8: ='Income Statement'!C16 -> 1074 | E8: ='Income Statement'!D16 -> 1091 | F8: ='Income Statement'!E16 -> 1137 | G8: ='Income Statement'!F16 -> 1216 | H8: ='Income Statement'!G16 -> 1355 | I8: ='Income Statement'!H16 -> 1385.2812 | J8: ='Income Statement'!I16 -> 1482.2509 | K8: ='Income Statement'!J16 -> 1600.831 | L8: ='Income Statement'!K16 -> 1728.8975
B9: Less: Change in Working Capital | C9: Change in Trade Receivables + Change in Inventories - Change in Trade Payables | D9: ='Cashflow Statement'!C31+'Cashflow Statement'!C32+'Cashflow Statement'!C34 -> -125 | E9: ='Cashflow Statement'!D31+'Cashflow Statement'!D32+'Cashflow Statement'!D34 -> -1089 | F9: ='Cashflow Statement'!E31+'Cashflow Statement'!E32+'Cashflow Statement'!E34 -> -828 | G9: ='Cashflow Statement'!F31+'Cashflow Statement'!F32+'Cashflow Statement'!F34 -> 1215 | H9: ='Cashflow Statement'!G31+'Cashflow Statement'!G32+'Cashflow Statement'!G34 -> -417 | I9: ='Cashflow Statement'!H31+'Cashflow Statement'!H32+'Cashflow Statement'!H34 -> 330.33997 | J9: ='Cashflow Statement'!I31+'Cashflow Statement'!I32+'Cashflow Statement'!I34 -> 238.7938 | K9: ='Cashflow Statement'!J31+'Cashflow Statement'!J32+'Cashflow Statement'!J34 -> 292.0107 | L9: ='Cashflow Statement'!K31+'Cashflow Statement'!K32+'Cashflow Statement'!K34 -> 315.37156
B10: Less: Capex | C10: Capital Expenditure | D10: ='Cashflow Statement'!C42 -> -741 | E10: ='Cashflow Statement'!D42 -> -1225 | F10: ='Cashflow Statement'!E42 -> -1174 | G10: ='Cashflow Statement'!F42 -> -1468 | H10: ='Cashflow Statement'!G42 -> -1254 | I10: ='Cashflow Statement'!H42 -> -1338.1652 | J10: ='Cashflow Statement'!I42 -> -1431.8368 | K10: ='Cashflow Statement'!J42 -> -1546.3837 | L10: ='Cashflow Statement'!K42 -> -1670.0944
B11: FCFF | C11: Sum of Above | D11: =(D7+D8+D9+D10) -> 8388.2753 | E11: =(E7+E8+E9+E10) -> 7696.9314 | F11: =(F7+F8+F9+F10) -> 9327.6486 | G11: =(G7+G8+G9+G10) -> 11240.57 | H11: =(H7+H8+H9+H10) -> 10129.217 | I11: =(I7+I8+I9+I10) -> 12118.42 | J11: =(J7+J8+J9+J10) -> 12909.149 | K11: =(K7+K8+K9+K10) -> 14033.656 | L11: =(L7+L8+L9+L10) -> 15220.733
B12: Discount Factor | I12: =1/(1+$C$28)^1 -> 0.90661839 | J12: =1/(1+$C$28)^2 -> 0.82195691 | K12: =1/(1+$C$28)^3 -> 0.74520125 | L12: =1/(1+$C$28)^4 -> 0.67561316
B13: PV of FCFF | I13: =I11*I12 -> 10986.782 | J13: =J11*J12 -> 10610.764 | K13: =K11*K12 -> 10457.898 | L13: =L11*L12 -> 10283.328
B14: WACC CALCULATION
B15: Cost of Equity (Ke) = Risk Free Rate + Beta(Equity Risk Premium) | C15: =C16+(C17*C18) -> 0.103
B16: Risk Free Rate | C16: 0.068
B17: Beta | C17: 0.5
B18: Equity Risk Premium | C18: 0.07
B20: Cost of Debt (Kd)
B21: Pre-Tax | C21: 0.075
B22: Post-Tax = Pre-Tax*(1-Tax Rate) | C22: =C21*(1-26%) -> 0.0555
B23: Market Cap (Equity) | C23: 490000
B24: Debt | C24: 1
B25: Weight of Equity = Market Cap/(Market Cap+Debt) | C25: =C23/(C23+C24) -> 0.99999796
B26: Weight of Debt = Debt/(Market Cap+Debt) | C26: =C24/(C23+C24) -> 2.0408122e-06
B28: WACC = (Weight of Equity × Cost of Equity) + (Weight of Debt × Post-tax Cost of Debt) | C28: =(C25*C15)+(C26*C22) -> 0.1029999
B29: Terminal Growth Rate (g) | C29: 0.05
B30: Terminal Value = FCFF_FY2030 / (WACC − g) | C30: =(L11*(1+C29))/(C28-C29) -> 301543.38
B31: PV of Terminal Value | C31: =C30/(1+C28)^4 -> 203726.68
B32: ENTERPRISE VALUE | C32: =SUM(I13:L13)+C31 -> 246065.45
B33: Enterprise Value = PV of FCFF (FY2026–FY2029) + PV of Terminal Value
B34: Less: Total Debt | C34: ='Balance Sheet'!G53 -> 1
B35: Add: Cash and Cash Equivalents | C35: ='Balance Sheet'!G27 -> 6071
B36: Equity Value | C36: =C32-C34+C35 -> 252135.45
B37: Shares Outstanding | C37: ='Balance Sheet'!G37 -> 235
B38: Implied Share Price | C38: =(C36/C37) -> 1072.9168
B39: Current Market Price | C39: 2083.6
B40: Upside / (Downside) vs CMP | C40: =(C38/C39)-1 -> -0.48506584
B44: Sensitivity Analysis — Implied Share Price (₹)
B45: WACC / Terminal Growth Rate
B46: =C38 -> 1072.9168 | C46: 0.04 | D46: 0.045 | E46: 0.05 | F46: 0.055 | G46: 0.06 | H46: 0.065 | I46: 0.07
...
